<robot name="robot_name">
  <link name="base_link">
  </link>
  <link name="round_frame_link">
    <inertial>
         <mass value="10.0"/>
         <origin xyz="0.2 0.0 0.0"/>
         <inertia ixx="0.1" ixy="0.0" ixz="0.0" iyy="0.1" iyz="0.0" izz="0.1"/>
    </inertial>
    <visual name="">
      <origin xyz="0.0 0.0 0.2" rpy="0.0 0.0 0.0"/>
      <geometry>
        <box size="0.23 0.16 0.1"/>
      </geometry>
      <material name="">
        <color rgba="1.0 1.0 1.0 1.0"/>
      </material>
    </visual>
    <collision>
      <origin xyz="0.0 0.0 0.2" rpy="0.0 0.0 0.0"/>
      <geometry>
        <box size="0.22 0.16 0.1"/>
      </geometry>
    </collision>
  </link>

  <joint name="round_frame_joint" type="fixed">
      <parent link="base_link"/>
      <child link="round_frame_link"/>
      <origin xyz="0.0 0.0 0.0" rpy="0.0 0.0 0.0"/>
  </joint>

  <link name="frame_link">
      <visual>
          <geometry>
              <box size="-0.1 0.1 0.05"/>
          </geometry>
          <origin xyz="0.0 0.0 0.075" rpy="0.0 0.0 0.0"/>
          <material name="white">
              <color rgba="1.0 0.0 0.0 1.0"/>
          </material>
      </visual>
      <inertial>
          <mass value="5"/>
          <origin xyz="0.0 0.0 0.075"/>
          <inertia ixx="0.1" ixy="0.0" ixz="0.0" iyy="0.1" iyz="0.0" izz="0.1"/>
      </inertial>
      <collision>
          <geometry>
              <box size="-0.1 0.1 0.05"/>
          </geometry>
          <origin xyz="0.0 0.0 0.075" rpy="0.0 0.0 0.0"/>
      </collision>
  </link>
  <joint name="frame_joint" type="fixed">
      <parent link="round_frame_link"/>
      <child link="frame_link"/>
      <origin xyz="-0.05 0.0 0.2" rpy="0.0 0.0 0.0"/>
  </joint>

  <!-- Wheels -->
  <link name="left_wheel_link"> 
    <inertial>
      <origin xyz="0.0 0.0 0.0" rpy="0.0 0.0 0.0"/>
      <mass value="0.2"/>
      <inertia ixx="0.1" ixy="0.0" ixz="0.0" iyy="0.1" iyz="0.0" izz="0.1"/>
    </inertial>
    <visual name="">
      <origin xyz="0.0 0.0 0.0" rpy="0.0 0.0 0.0"/>
      <geometry>
        <cylinder radius="0.03" length="0.02"/>
      </geometry>
      <material name="">
        <color rgba="0.0 0.0 1.0 1.0"/>
      </material>
    </visual>
    <collision>
      <origin xyz="0.0 0.0 0.0" rpy="0.0 0.0 0.0"/>
      <geometry>
        <cylinder radius="0.03" length="0.04"/>
      </geometry>
    </collision>
    <friction>
      <ode>
        <mu>0.02</mu>     
        <mu2>0.02</mu2>   
      </ode>
    </friction>
  </link>
  <joint name="left_wheel_joint" type="continuous">
      <parent link="frame_link"/>
      <child link="left_wheel_link"/>
      <origin xyz="0.14 0.08 -0.05" rpy="-1.57 0.0 0.0"/>
      <axis xyz="0.0 0.0 1.0"/>
  </joint>

  <link name="right_wheel_link">
    <inertial>
      <origin xyz="0.0 0.0 0.0" rpy="0.0 0.0 0.0"/>
      <mass value="0.2"/>
      <inertia ixx="0.1" ixy="0.0" ixz="0.0" iyy="0.1" iyz="0.0" izz="0.1"/>
    </inertial>
    <visual name="">
      <origin xyz="0.0 0.0 0.0" rpy="0.0 0.0 0.0"/>
      <geometry>
        <cylinder radius="0.03" length="0.02"/>
      </geometry>
      <material name="">
        <color rgba="0.0 0.0 1.0 1.0"/>
      </material>
    </visual>
    <collision>
      <origin xyz="0.0 0.0 0.0" rpy="0.0 0.0 0.0"/>
      <geometry>
        <cylinder radius="0.03" length="0.04"/>
      </geometry>
    </collision>
    <friction>
      <ode>
        <mu>0.02</mu>     
        <mu2>0.02</mu2>   
      </ode>
    </friction>
  </link>
  <joint name="right_wheel_joint" type="continuous">
      <parent link="frame_link"/>
      <child link="right_wheel_link"/>
      <origin xyz="0.14 -0.08 -0.05" rpy="1.57 0.0 0.0"/>
      <axis xyz="0.0 0.0 1.0"/>
  </joint>

  <link name="mid_wheel_link">
    <inertial>
      <origin xyz="0.0 0.0 0.0" rpy="0.0 0.0 0.0"/>
      <mass value="5"/>
      <inertia ixx="0.1" ixy="0.0" ixz="0.0" iyy="0.1" iyz="0.0" izz="0.1"/>
    </inertial>
    <visual name="">
      <origin xyz="0.0 0.0 0.0" rpy="0.0 0.0 0.0"/>
      <geometry>
        <cylinder radius="0.03" length="0.04"/>
      </geometry>
      <material name="">
        <color rgba="0.0 1.0 0.0 1.0"/>
      </material>
    </visual>
    <collision>
      <origin xyz="0.0 0.0 0.0" rpy="0.0 0.0 0.0"/>
      <geometry>
        <cylinder radius="0.03" length="0.04"/>
      </geometry>
    </collision>
    <friction>
      <ode>
        <mu>0.02</mu>     
        <mu2>0.02</mu2>   
      </ode>
    </friction>
  </link>
  <joint name="mid_wheel_joint" type="continuous">
      <parent link="frame_link"/>
      <child link="mid_wheel_link"/>
      <origin xyz="-0.03 0.0 -0.05" rpy="-1.57 0.0 0.0"/>
      <axis xyz="0.0 0.0 1.0"/>
  </joint>


  <!-- Transmission -->
  <transmission name="tran1">
        <type>transmission_interface/SimpleTransmission</type>
        <joint name="left_wheel_joint">
            <hardwareInterface>hardware_interface/EffortJointInterface</hardwareInterface>
        </joint>
        <actuator name="motor1">
            <hardwareInterface>hardware_interface/EffortJointInterface</hardwareInterface>
            <mechanicalReduction>1</mechanicalReduction>
        </actuator>
  </transmission>

  <transmission name="tran2">
    <type>transmission_interface/SimpleTransmission</type>
    <joint name="right_wheel_joint">
        <hardwareInterface>hardware_interface/EffortJointInterface</hardwareInterface>
    </joint>
    <actuator name="motor2">
        <hardwareInterface>hardware_interface/EffortJointInterface</hardwareInterface>
        <mechanicalReduction>1</mechanicalReduction>
    </actuator>
  </transmission>


  <!--Gazebo-->
    <gazebo reference="round_frame_link">
        <material>Gazebo/Orange</material>
    </gazebo>
    <gazebo reference="frame_link">
        <material>Gazebo/Red</material>
    </gazebo>
    <gazebo reference="left_wheel_link">
        <material>Gazebo/Blue</material>
    </gazebo>
    <gazebo reference="right_wheel_link">
        <material>Gazebo/Blue</material>
    </gazebo>
    <gazebo reference="mid_wheel_link">
        <material>Gazebo/Green</material>
    </gazebo>
    <gazebo reference="base_cam_link">
        <material>Gazebo/Yellow</material>
    </gazebo>

    <gazebo>
        <plugin name="gazebo_ros_control" filename="libgazebo_ros_control.so">
            <robotNamespace>/my_diffbot</robotNamespace>
        </plugin>
    </gazebo>

</robot>